Workbook

Sheet 01_Base
A1: ID_Atendimento | B1: Data_Abertura | C1: Canal | D1: Equipe | E1: Atendente | F1: Motivo | G1: Status | H1: Tempo_1a_Resposta_min | I1: Tempo_Atendimento_min | J1: Resolvido_1o_Contato | K1: Nota_CSAT | L1: Semana | M1: Prazo_SLA_min | N1: Dentro_SLA
A2: AT-00001 | B2: 46266 | C2: Telefone | D2: Equipe A | E2: Analista 01 | F2: Atraso na entrega | G2: Resolvido | H2: 0.7 | I2: 12.7 | J2: Sim | L2: =B2-WEEKDAY(B2,2)+1 -> 46265 | M2: =IFERROR(INDEX(02_Parâmetros!$B$14:$B$17,MATCH(C2,02_Parâmetros!$A$14:$A$17,0)),"") -> 1 | N2: =IF(OR(H2="",M2=""),"",IF(H2<=M2,"Sim","Não")) -> Sim
A3: AT-00002 | B3: 46266 | C3: Telefone | D3: Equipe C | E3: Analista 07 | F3: Produto incorreto ou avariado | G3: Resolvido | H3: 0.9 | I3: 22.3 | J3: Não | L3: =B3-WEEKDAY(B3,2)+1 -> 46265 | M3: =IFERROR(INDEX(02_Parâmetros!$B$14:$B$17,MATCH(C3,02_Parâmetros!$A$14:$A$17,0)),"") -> 1 | N3: =IF(OR(H3="",M3=""),"",IF(H3<=M3,"Sim","Não")) -> Sim
A4: AT-00003 | B4: 46266 | C4: WhatsApp | D4: Equipe C | E4: Analista 08 | F4: Atraso na entrega | G4: Resolvido | H4: 20.7 | I4: 7.7 | J4: Sim | K4: 3 | L4: =B4-WEEKDAY(B4,2)+1 -> 46265 | M4: =IFERROR(INDEX(02_Parâmetros!$B$14:$B$17,MATCH(C4,02_Parâmetros!$A$14:$A$17,0)),"") -> 10 | N4: =IF(OR(H4="",M4=""),"",IF(H4<=M4,"Sim","Não")) -> Não
A5: AT-00004 | B5: 46266 | C5: Telefone | D5: Equipe C | E5: Analista 07 | F5: Atraso na entrega | G5: Resolvido | H5: 1 | I5: 12.1 | J5: Não | L5: =B5-WEEKDAY(B5,2)+1 -> 46265 | M5: =IFERROR(INDEX(02_Parâmetros!$B$14:$B$17,MATCH(C5,02_Parâmetros!$A$14:$A$17,0)),"") -> 1 | N5: =IF(OR(H5="",M5=""),"",IF(H5<=M5,"Sim","Não")) -> Sim
A6: AT-00005 | B6: 46266 | C6: WhatsApp | D6: Equipe A | E6: Analista 03 | F6: Dúvida sobre o pedido | G6: Resolvido | H6: 5.7 | I6: 6.5 | J6: Sim | L6: =B6-WEEKDAY(B6,2)+1 -> 46265 | M6: =IFERROR(INDEX(02_Parâmetros!$B$14:$B$17,MATCH(C6,02_Parâmetros!$A$14:$A$17,0)),"") -> 10 | N6: =IF(OR(H6="",M6=""),"",IF(H6<=M6,"Sim","Não")) -> Sim
A7: AT-00006 | B7: 46266 | C7: WhatsApp | D7: Equipe C | E7: Analista 08 | F7: Cadastro ou acesso | G7: Resolvido | H7: 7.9 | I7: 5 | J7: Sim | L7: =B7-WEEKDAY(B7,2)+1 -> 46265 | M7: =IFERROR(INDEX(02_Parâmetros!$B$14:$B$17,MATCH(C7,02_Parâmetros!$A$14:$A$17,0)),"") -> 10 | N7: =IF(OR(H7="",M7=""),"",IF(H7<=M7,"Sim","Não")) -> Sim
A8: AT-00007 | B8: 46266 | C8: WhatsApp | D8: Equipe A | E8: Analista 02 | F8: Produto incorreto ou avariado | G8: Resolvido | H8: 7.9 | I8: 8.2 | J8: Sim | L8: =B8-WEEKDAY(B8,2)+1 -> 46265 | M8: =IFERROR(INDEX(02_Parâmetros!$B$14:$B$17,MATCH(C8,02_Parâmetros!$A$14:$A$17,0)),"") -> 10 | N8: =IF(OR(H8="",M8=""),"",IF(H8<=M8,"Sim","Não")) -> Sim
A9: AT-00008 | B9: 46266 | C9: WhatsApp | D9: Equipe B | E9: Analista 04 | F9: Produto incorreto ou avariado | G9: Resolvido | H9: 5.6 | I9: 8.2 | J9: Sim | K9: 1 | L9: =B9-WEEKDAY(B9,2)+1 -> 46265 | M9: =IFERROR(INDEX(02_Parâmetros!$B$14:$B$17,MATCH(C9,02_Parâmetros!$A$14:$A$17,0)),"") -> 10 | N9: =IF(OR(H9="",M9=""),"",IF(H9<=M9,"Sim","Não")) -> Sim
A10: AT-00009 | B10: 46266 | C10: E-mail | D10: Equipe A | E10: Analista 02 | F10: Cobrança ou pagamento | G10: Resolvido | H10: 77.4 | I10: 12.2 | J10: Sim | L10: =B10-WEEKDAY(B10,2)+1 -> 46265 | M10: =IFERROR(INDEX(02_Parâmetros!$B$14:$B$17,MATCH(C10,02_Parâmetros!$A$14:$A$17,0)),"") -> 240 | N10: =IF(OR(H10="",M10=""),"",IF(H10<=M10,"Sim","Não")) -> Sim
A11: AT-00010 | B11: 46266 | C11: Chat | D11: Equipe A | E11: Analista 03 | F11: Produto incorreto ou avariado | G11: Resolvido | H11: 1.4 | I11: 7.2 | J11: Sim | L11: =B11-WEEKDAY(B11,2)+1 -> 46265 | M11: =IFERROR(INDEX(02_Parâmetros!$B$14:$B$17,MATCH(C11,02_Parâmetros!$A$14:$A$17,0)),"") -> 2 | N11: =IF(OR(H11="",M11=""),"",IF(H11<=M11,"Sim","Não")) -> Sim
A12: AT-00011 | B12: 46266 | C12: Chat | D12: Equipe C | E12: Analista 07 | F12: Produto incorreto ou avariado | G12: Resolvido | H12: 0.8 | I12: 13.1 | J12: Sim | L12: =B12-WEEKDAY(B12,2)+1 -> 46265 | M12: =IFERROR(INDEX(02_Parâmetros!$B$14:$B$17,MATCH(C12,02_Parâmetros!$A$14:$A$17,0)),"") -> 2 | N12: =IF(OR(H12="",M12=""),"",IF(H12<=M12,"Sim","Não")) -> Sim
A13: AT-00012 | B13: 46266 | C13: Telefone | D13: Equipe B | E13: Analista 06 | F13: Dúvida sobre o pedido | G13: Resolvido | H13: 0.4 | I13: 10.8 | J13: Sim | K13: 4 | L13: =B13-WEEKDAY(B13,2)+1 -> 46265 | M13: =IFERROR(INDEX(02_Parâmetros!$B$14:$B$17,MATCH(C13,02_Parâmetros!$A$14:$A$17,0)),"") -> 1 | N13: =IF(OR(H13="",M13=""),"",IF(H13<=M13,"Sim","Não")) -> Sim
A14: AT-00013 | B14: 46266 | C14: WhatsApp | D14: Equipe A | E14: Analista 03 | F14: Cadastro ou acesso | G14: Resolvido | H14: 9 | I14: 6.8 | J14: Sim | K14: 4 | L14: =B14-WEEKDAY(B14,2)+1 -> 46265 | M14: =IFERROR(INDEX(02_Parâmetros!$B$14:$B$17,MATCH(C14,02_Parâmetros!$A$14:$A$17,0)),"") -> 10 | N14: =IF(OR(H14="",M14=""),"",IF(H14<=M14,"Sim","Não")) -> Sim
A15: AT-00014 | B15: 46266 | C15: WhatsApp | D15: Equipe B | E15: Analista 06 | F15: Produto incorreto ou avariado | G15: Resolvido | H15: 2.6 | I15: 9.7 | J15: Sim | K15: 5 | L15: =B15-WEEKDAY(B15,2)+1 -> 46265 | M15: =IFERROR(INDEX(02_Parâmetros!$B$14:$B$17,MATCH(C15,02_Parâmetros!$A$14:$A$17,0)),"") -> 10 | N15: =IF(OR(H15="",M15=""),"",IF(H15<=M15,"Sim","Não")) -> Sim
A16: AT-00015 | B16: 46266 | C16: E-mail | D16: Equipe C | E16: Analista 08 | F16: Dúvida sobre o pedido | G16: Resolvido | H16: 218.7 | I16: 9.7 | J16: Não | K16: 4 | L16: =B16-WEEKDAY(B16,2)+1 -> 46265 | M16: =IFERROR(INDEX(02_Parâmetros!$B$14:$B$17,MATCH(C16,02_Parâmetros!$A$14:$A$17,0)),"") -> 240 | N16: =IF(OR(H16="",M16=""),"",IF(H16<=M16,"Sim","Não")) -> Sim
A17: AT-00016 | B17: 46266 | C17: WhatsApp | D17: Equipe A | E17: Analista 01 | F17: Dúvida sobre o pedido | G17: Resolvido | H17: 9 | I17: 6.5 | J17: Não | K17: 5 | L17: =B17-WEEKDAY(B17,2)+1 -> 46265 | M17: =IFERROR(INDEX(02_Parâmetros!$B$14:$B$17,MATCH(C17,02_Parâmetros!$A$14:$A$17,0)),"") -> 10 | N17: =IF(OR(H17="",M17=""),"",IF(H17<=M17,"Sim","Não")) -> Sim
A18: AT-00017 | B18: 46266 | C18: E-mail | D18: Equipe C | E18: Analista 08 | F18: Produto incorreto ou avariado | G18: Resolvido | H18: 92.8 | I18: 10 | J18: Sim | L18: =B18-WEEKDAY(B18,2)+1 -> 46265 | M18: =IFERROR(INDEX(02_Parâmetros!$B$14:$B$17,MATCH(C18,02_Parâmetros!$A$14:$A$17,0)),"") -> 240 | N18: =IF(OR(H18="",M18=""),"",IF(H18<=M18,"Sim","Não")) -> Sim
A19: AT-00018 | B19: 46266 | C19: WhatsApp | D19: Equipe A | E19: Analista 01 | F19: Produto incorreto ou avariado | G19: Resolvido | H19: 9.8 | I19: 9.4 | J19: Sim | K19: 3 | L19: =B19-WEEKDAY(B19,2)+1 -> 46265 | M19: =IFERROR(INDEX(02_Parâmetros!$B$14:$B$17,MATCH(C19,02_Parâmetros!$A$14:$A$17,0)),"") -> 10 | N19: =IF(OR(H19="",M19=""),"",IF(H19<=M19,"Sim","Não")) -> Sim
A20: AT-00019 | B20: 46266 | C20: Telefone | D20: Equipe B | E20: Analista 06 | F20: Atraso na entrega | G20: Resolvido | H20: 1 | I20: 15.7 | J20: Sim | K20: 3 | L20: =B20-WEEKDAY(B20,2)+1 -> 46265 | M20: =IFERROR(INDEX(02_Parâmetros!$B$14:$B$17,MATCH(C20,02_Parâmetros!$A$14:$A$17,0)),"") -> 1 | N20: =IF(OR(H20="",M20=""),"",IF(H20<=M20,"Sim","Não")) -> Sim
A21: AT-00020 | B21: 46266 | C21: WhatsApp | D21: Equipe B | E21: Analista 05 | F21: Cobrança ou pagamento | G21: Resolvido | H21: 7 | I21: 4.3 | J21: Sim | L21: =B21-WEEKDAY(B21,2)+1 -> 46265 | M21: =IFERROR(INDEX(02_Parâmetros!$B$14:$B$17,MATCH(C21,02_Parâmetros!$A$14:$A$17,0)),"") -> 10 | N21: =IF(OR(H21="",M21=""),"",IF(H21<=M21,"Sim","Não")) -> Sim
A22: AT-00021 | B22: 46266 | C22: Chat | D22: Equipe C | E22: Analista 08 | F22: Atraso na entrega | G22: Resolvido | H22: 1.7 | I22: 20 | J22: Não | K22: 4 | L22: =B22-WEEKDAY(B22,2)+1 -> 46265 | M22: =IFERROR(INDEX(02_Parâmetros!$B$14:$B$17,MATCH(C22,02_Parâmetros!$A$14:$A$17,0)),"") -> 2 | N22: =IF(OR(H22="",M22=""),"",IF(H22<=M22,"Sim","Não")) -> Sim
A23: AT-00022 | B23: 46266 | C23: Telefone | D23: Equipe B | E23: Analista 06 | F23: Cobrança ou pagamento | G23: Resolvido | H23: 0.8 | I23: 15.2 | J23: Sim | L23: =B23-WEEKDAY(B23,2)+1 -> 46265 | M23: =IFERROR(INDEX(02_Parâmetros!$B$14:$B$17,MATCH(C23,02_Parâmetros!$A$14:$A$17,0)),"") -> 1 | N23: =IF(OR(H23="",M23=""),"",IF(H23<=M23,"Sim","Não")) -> Sim
A24: AT-00023 | B24: 46266 | C24: WhatsApp | D24: Equipe A | E24: Analista 01 | F24: Dúvida sobre o pedido | G24: Resolvido | H24: 9.7 | I24: 6.3 | J24: Sim | L24: =B24-WEEKDAY(B24,2)+1 -> 46265 | M24: =IFERROR(INDEX(02_Parâmetros!$B$14:$B$17,MATCH(C24,02_Parâmetros!$A$14:$A$17,0)),"") -> 10 | N24: =IF(OR(H24="",M24=""),"",IF(H24<=M24,"Sim","Não")) -> Sim
A25: AT-00024 | B25: 46267 | C25: E-mail | D25: Equipe B | E25: Analista 05 | F25: Atraso na entrega | G25: Resolvido | H25: 78 | I25: 10.7 | J25: Sim | K25: 5 | L25: =B25-WEEKDAY(B25,2)+1 -> 46265 | M25: =IFERROR(INDEX(02_Parâmetros!$B$14:$B$17,MATCH(C25,02_Parâmetros!$A$14:$A$17,0)),"") -> 240 | N25: =IF(OR(H25="",M25=""),"",IF(H25<=M25,"Sim","Não")) -> Sim
A26: AT-00025 | B26: 46267 | C26: WhatsApp | D26: Equipe B | E26: Analista 06 | F26: Atraso na entrega | G26: Resolvido | H26: 4.4 | I26: 7.2 | J26: Não | L26: =B26-WEEKDAY(B26,2)+1 -> 46265 | M26: =IFERROR(INDEX(02_Parâmetros!$B$14:$B$17,MATCH(C26,02_Parâmetros!$A$14:$A$17,0)),"") -> 10 | N26: =IF(OR(H26="",M26=""),"",IF(H26<=M26,"Sim","Não")) -> Sim
A27: AT-00026 | B27: 46267 | C27: E-mail | D27: Equipe A | E27: Analista 02 | F27: Cadastro ou acesso | G27: Resolvido | H27: 146.5 | I27: 8.3 | J27: Sim | K27: 4 | L27: =B27-WEEKDAY(B27,2)+1 -> 46265 | M27: =IFERROR(INDEX(02_Parâmetros!$B$14:$B$17,MATCH(C27,02_Parâmetros!$A$14:$A$17,0)),"") -> 240 | N27: =IF(OR(H27="",M27=""),"",IF(H27<=M27,"Sim","Não")) -> Sim
A28: AT-00027 | B28: 46267 | C28: Chat | D28: Equipe C | E28: Analista 08 | F28: Cobrança ou pagamento | G28: Resolvido | H28: 1.9 | I28: 10.2 | J28: Sim | K28: 4 | L28: =B28-WEEKDAY(B28,2)+1 -> 46265 | M28: =IFERROR(INDEX(02_Parâmetros!$B$14:$B$17,MATCH(C28,02_Parâmetros!$A$14:$A$17,0)),"") -> 2 | N28: =IF(OR(H28="",M28=""),"",IF(H28<=M28,"Sim","Não")) -> Sim
A29: AT-00028 | B29: 46267 | C29: WhatsApp | D29: Equipe C | E29: Analista 07 | F29: Produto incorreto ou avariado | G29: Resolvido | H29: 4 | I29: 7.7 | J29: Não | L29: =B29-WEEKDAY(B29,2)+1 -> 46265 | M29: =IFERROR(INDEX(02_Parâmetros!$B$14:$B$17,MATCH(C29,02_Parâmetros!$A$14:$A$17,0)),"") -> 10 | N29: =IF(OR(H29="",M29=""),"",IF(H29<=M29,"Sim","Não")) -> Sim
A30: AT-00029 | B30: 46267 | C30: WhatsApp | D30: Equipe C | E30: Analista 07 | F30: Dúvida sobre o pedido | G30: Resolvido | H30: 13.1 | I30: 6.3 | J30: Sim | L30: =B30-WEEKDAY(B30,2)+1 -> 46265 | M30: =IFERROR(INDEX(02_Parâmetros!$B$14:$B$17,MATCH(C30,02_Parâmetros!$A$14:$A$17,0)),"") -> 10 | N30: =IF(OR(H30="",M30=""),"",IF(H30<=M30,"Sim","Não")) -> Não
A31: AT-00030 | B31: 46267 | C31: Telefone | D31: Equipe C | E31: Analista 08 | F31: Cobrança ou pagamento | G31: Resolvido | H31: 0.9 | I31: 15.7 | J31: Sim | K31: 4 | L31: =B31-WEEKDAY(B31,2)+1 -> 46265 | M31: =IFERROR(INDEX(02_Parâmetros!$B$14:$B$17,MATCH(C31,02_Parâmetros!$A$14:$A$17,0)),"") -> 1 | N31: =IF(OR(H31="",M31=""),"",IF(H31<=M31,"Sim","Não")) -> Sim
A32: AT-00031 | B32: 46267 | C32: WhatsApp | D32: Equipe B | E32: Analista 06 | F32: Produto incorreto ou avariado | G32: Resolvido | H32: 9.3 | I32: 11.3 | J32: Sim | K32: 5 | L32: =B32-WEEKDAY(B32,2)+1 -> 46265 | M32: =IFERROR(INDEX(02_Parâmetros!$B$14:$B$17,MATCH(C32,02_Parâmetros!$A$14:$A$17,0)),"") -> 10 | N32: =IF(OR(H32="",M32=""),"",IF(H32<=M32,"Sim","Não")) -> Sim
A33: AT-00032 | B33: 46267 | C33: E-mail | D33: Equipe B | E33: Analista 04 | F33: Cobrança ou pagamento | G33: Resolvido | H33: 134.6 | I33: 13.3 | J33: Sim | K33: 5 | L33: =B33-WEEKDAY(B33,2)+1 -> 46265 | M33: =IFERROR(INDEX(02_Parâmetros!$B$14:$B$17,MATCH(C33,02_Parâmetros!$A$14:$A$17,0)),"") -> 240 | N33: =IF(OR(H33="",M33=""),"",IF(H33<=M33,"Sim","Não")) -> Sim
A34: AT-00033 | B34: 46267 | C34: WhatsApp | D34: Equipe B | E34: Analista 04 | F34: Cancelamento | G34: Resolvido | H34: 7.7 | I34: 7.2 | J34: Sim | L34: =B34-WEEKDAY(B34,2)+1 -> 46265 | M34: =IFERROR(INDEX(02_Parâmetros!$B$14:$B$17,MATCH(C34,02_Parâmetros!$A$14:$A$17,0)),"") -> 10 | N34: =IF(OR(H34="",M34=""),"",IF(H34<=M34,"Sim","Não")) -> Sim
A35: AT-00034 | B35: 46267 | C35: E-mail | D35: Equipe A | E35: Analista 03 | F35: Produto incorreto ou avariado | G35: Resolvido | H35: 358.8 | I35: 14.9 | J35: Sim | L35: =B35-WEEKDAY(B35,2)+1 -> 46265 | M35: =IFERROR(INDEX(02_Parâmetros!$B$14:$B$17,MATCH(C35,02_Parâmetros!$A$14:$A$17,0)),"") -> 240 | N35: =IF(OR(H35="",M35=""),"",IF(H35<=M35,"Sim","Não")) -> Não
A36: AT-00035 | B36: 46267 | C36: WhatsApp | D36: Equipe A | E36: Analista 01 | F36: Atraso na entrega | G36: Resolvido | H36: 2.8 | I36: 8.3 | J36: Sim | K36: 5 | L36: =B36-WEEKDAY(B36,2)+1 -> 46265 | M36: =IFERROR(INDEX(02_Parâmetros!$B$14:$B$17,MATCH(C36,02_Parâmetros!$A$14:$A$17,0)),"") -> 10 | N36: =IF(OR(H36="",M36=""),"",IF(H36<=M36,"Sim","Não")) -> Sim
A37: AT-00036 | B37: 46267 | C37: WhatsApp | D37: Equipe C | E37: Analista 08 | F37: Atraso na entrega | G37: Resolvido | H37: 7.5 | I37: 15 | J37: Não | L37: =B37-WEEKDAY(B37,2)+1 -> 46265 | M37: =IFERROR(INDEX(02_Parâmetros!$B$14:$B$17,MATCH(C37,02_Parâmetros!$A$14:$A$17,0)),"") -> 10 | N37: =IF(OR(H37="",M37=""),"",IF(H37<=M37,"Sim","Não")) -> Sim
A38: AT-00037 | B38: 46267 | C38: WhatsApp | D38: Equipe B | E38: Analista 05 | F38: Cadastro ou acesso | G38: Resolvido | I38: 5.8 | J38: Sim | L38: =B38-WEEKDAY(B38,2)+1 -> 46265 | M38: =IFERROR(INDEX(02_Parâmetros!$B$14:$B$17,MATCH(C38,02_Parâmetros!$A$14:$A$17,0)),"") -> 10 | N38: =IF(OR(H38="",M38=""),"",IF(H38<=M38,"Sim","Não"))
A39: AT-00038 | B39: 46267 | C39: Chat | D39: Equipe A | E39: Analista 01 | F39: Cadastro ou acesso | G39: Resolvido | H39: 1.3 | I39: 5.7 | J39: Sim | L39: =B39-WEEKDAY(B39,2)+1 -> 46265 | M39: =IFERROR(INDEX(02_Parâmetros!$B$14:$B$17,MATCH(C39,02_Parâmetros!$A$14:$A$17,0)),"") -> 2 | N39: =IF(OR(H39="",M39=""),"",IF(H39<=M39,"Sim","Não")) -> Sim
A40: AT-00039 | B40: 46267 | C40: Telefone | D40: Equipe B | E40: Analista 06 | F40: Produto incorreto ou avariado | G40: Resolvido | H40: 0.5 | I40: 20.2 | J40: Sim | L40: =B40-WEEKDAY(B40,2)+1 -> 46265 | M40: =IFERROR(INDEX(02_Parâmetros!$B$14:$B$17,MATCH(C40,02_Parâmetros!$A$14:$A$17,0)),"") -> 1 | N40: =IF(OR(H40="",M40=""),"",IF(H40<=M40,"Sim","Não")) -> Sim
...

Sheet 02_Parâmetros
A1: Parâmetros e regras de cálculo
A2: METAS ILUSTRATIVAS: servem para demonstrar alertas. Não são resultados reais da Daki nem de nenhum empregador anterior. Os dados da aba 01_Base são sintéticos.
A3: Células amarelas com texto azul podem ser alteradas. O restante é fórmula ou regra fixa.
A4: Indicador | B4: Meta | C4: Sentido | D4: Tolerância (Atenção) | E4: Regra de cálculo e elegibilidade
A5: Volume: utilização da capacidade (limite) | B5: 0.9 | C5: Menor | D5: 0.1 | E5: Volume médio por dia útil ÷ capacidade diária (atendentes × meta de produtividade). Acima do limite = pressão.
A6: TMA (min) | B6: 9 | C6: Menor | D6: 1 | E6: Elegíveis: status Resolvido. Média de Tempo_Atendimento_min.
A7: SLA de 1ª resposta | B7: 0.92 | C7: Maior | D7: 0.03 | E7: Elegíveis: registros com Tempo_1a_Resposta_min medido. Dentro do SLA = tempo ≤ prazo do canal.
A8: Produtividade (resolvidos por atendente por dia útil) | B8: 3.5 | C8: Maior | D8: 0.5 | E8: Resolvidos ÷ (atendentes × dias úteis do período). Atendentes: os da equipe filtrada, ou todos.
A9: CSAT | B9: 0.85 | C9: Maior | D9: 0.03 | E9: Elegíveis: registros com nota. Satisfeito = nota 4 ou 5.
A10: FCR | B10: 0.78 | C10: Maior | D10: 0.03 | E10: Elegíveis: status Resolvido. FCR = Resolvido_1o_Contato igual a Sim.
A12: Prazo da 1ª resposta por canal
A13: Canal | B13: Prazo (min) | C13: Observação
A14: WhatsApp | B14: 10 | C14: ilustrativo
A15: Chat | B15: 2 | C15: ilustrativo
A16: E-mail | B16: 240 | C16: ilustrativo
A17: Telefone | B17: 1 | C17: ilustrativo
A19: Atendentes e equipes
A20: Atendente | B20: Equipe
A21: Analista 01 | B21: Equipe A
A22: Analista 02 | B22: Equipe A
A23: Analista 03 | B23: Equipe A
A24: Analista 04 | B24: Equipe B
A25: Analista 05 | B25: Equipe B
A26: Analista 06 | B26: Equipe B
A27: Analista 07 | B27: Equipe C
A28: Analista 08 | B28: Equipe C
A30: Listas
A31: Equipes
A32: Equipe A
A33: Equipe B
A34: Equipe C
A36: Motivos
A37: Atraso na entrega
A38: Cobrança ou pagamento
A39: Produto incorreto ou avariado
A40: Dúvida sobre o pedido
A41: Cancelamento
A42: Cadastro ou acesso
A45: Período da base
A46: Primeira abertura | B46: =MIN(01_Base!$B$2:$B$1201) -> 46266
...

Sheet 03_Dashboard
B2: Dashboard de performance operacional e CX
B3: Base sintética de 1.200 atendimentos (set e out de 2026). Metas ilustrativas, sem relação com resultados reais de qualquer empresa. | V3: Cálculos de apoio (não editar)
B5: Período: de | D5: até | G5: Canal | K5: Equipe | O5: Motivo | V5: Critério canal | W5: =IF($G$6="Todos","*",$G$6) -> *
B6: 46266 | D6: 46325 | G6: Todos | K6: Todos | O6: Todos | V6: Critério equipe | W6: =IF($K$6="Todos","*",$K$6) -> *
B7: =IF(D6<B6,"Atenção: a data final é anterior à inicial.","Para limpar os filtros: Canal, Equipe e Motivo em Todos, e as datas em 01/09/2026 e 30/10/2026.") -> Para limpar os filtros: Canal, Equipe e Motivo em Todos, e as datas em 01/09/2026 e 30/10/2026. | V7: Critério motivo | W7: =IF($O$6="Todos","*",$O$6) -> *
V8: Data inicial | W8: =$B$6 -> 46266
B9: Volume de atendimentos | E9: TMA | H9: SLA de 1ª resposta | K9: Produtividade | N9: CSAT | Q9: FCR | V9: Data final | W9: =$D$6 -> 46325
B10: =$W$14 -> 1200 | E10: =$W$16 -> 9.527883 | H10: =$W$19 -> 0.8814433 | K10: =$W$25 -> 3.3011364 | N10: =$W$22 -> 0.80930233 | Q10: =$W$24 -> 0.75731497 | V10: Atendentes no filtro | W10: =IF($K$6="Todos",COUNTA(02_Parâmetros!$A$21:$A$28),COUNTIF(02_Parâmetros!$B$21:$B$28,$K$6)) -> 8
V11: Dias úteis no período | W11: =NETWORKDAYS(W8,W9) -> 44
B12: ="média de "&ROUND($W$27,1)&" por dia · "&ROUND($W$28*100,0)&"% da capacidade" -> média de 27.3 por dia · 97% da capacidade | E12: ="meta ≤ "&ROUND(02_Parâmetros!$B$6,1)&" min" -> meta ≤ 9 min | H12: ="meta ≥ "&ROUND(02_Parâmetros!$B$7*100,0)&"%" -> meta ≥ 92% | K12: ="meta ≥ "&ROUND(02_Parâmetros!$B$8,1)&" resolvidos por atendente/dia" -> meta ≥ 3.5 resolvidos por atendente/dia | N12: ="meta ≥ "&ROUND(02_Parâmetros!$B$9*100,0)&"%"&" · "&$W$20&" respostas" -> meta ≥ 85% · 430 respostas | Q12: ="meta ≥ "&ROUND(02_Parâmetros!$B$10*100,0)&"%" -> meta ≥ 78%
B13: =IF($W$14=0,"Sem dados",IF(02_Parâmetros!$C$5="Maior",IF($W$28>=02_Parâmetros!$B$5,"Na meta",IF($W$28>=02_Parâmetros!$B$5-02_Parâmetros!$D$5,"Atenção","Abaixo")),IF($W$28<=02_Parâmetros!$B$5,"Na meta",IF($W$28<=02_Parâmetros!$B$5+02_Parâmetros!$D$5,"Atenção","Abaixo")))) -> Atenção | E13: =IF($W$14=0,"Sem dados",IF(02_Parâmetros!$C$6="Maior",IF($W$16>=02_Parâmetros!$B$6,"Na meta",IF($W$16>=02_Parâmetros!$B$6-02_Parâmetros!$D$6,"Atenção","Abaixo")),IF($W$16<=02_Parâmetros!$B$6,"Na meta",IF($W$16<=02_Parâmetros!$B$6+02_Parâmetros!$D$6,"Atenção","Abaixo")))) -> Atenção | H13: =IF($W$14=0,"Sem dados",IF(02_Parâmetros!$C$7="Maior",IF($W$19>=02_Parâmetros!$B$7,"Na meta",IF($W$19>=02_Parâmetros!$B$7-02_Parâmetros!$D$7,"Atenção","Abaixo")),IF($W$19<=02_Parâmetros!$B$7,"Na meta",IF($W$19<=02_Parâmetros!$B$7+02_Parâmetros!$D$7,"Atenção","Abaixo")))) -> Abaixo | K13: =IF($W$14=0,"Sem dados",IF(02_Parâmetros!$C$8="Maior",IF($W$25>=02_Parâmetros!$B$8,"Na meta",IF($W$25>=02_Parâmetros!$B$8-02_Parâmetros!$D$8,"Atenção","Abaixo")),IF($W$25<=02_Parâmetros!$B$8,"Na meta",IF($W$25<=02_Parâmetros!$B$8+02_Parâmetros!$D$8,"Atenção","Abaixo")))) -> Atenção | N13: =IF($W$14=0,"Sem dados",IF(02_Parâmetros!$C$9="Maior",IF($W$22>=02_Parâmetros!$B$9,"Na meta",IF($W$22>=02_Parâmetros!$B$9-02_Parâmetros!$D$9,"Atenção","Abaixo")),IF($W$22<=02_Parâmetros!$B$9,"Na meta",IF($W$22<=02_Parâmetros!$B$9+02_Parâmetros!$D$9,"Atenção","Abaixo")))) -> Abaixo | Q13: =IF($W$14=0,"Sem dados",IF(02_Parâmetros!$C$10="Maior",IF($W$24>=02_Parâmetros!$B$10,"Na meta",IF($W$24>=02_Parâmetros!$B$10-02_Parâmetros!$D$10,"Atenção","Abaixo")),IF($W$24<=02_Parâmetros!$B$10,"Na meta",IF($W$24<=02_Parâmetros!$B$10+02_Parâmetros!$D$10,"Atenção","Abaixo")))) -> Atenção
V14: Volume | W14: =COUNTIFS(01_Base!$B$2:$B$1201,">="&$W$8,01_Base!$B$2:$B$1201,"<="&$W$9,01_Base!$C$2:$C$1201,$W$5,01_Base!$D$2:$D$1201,$W$6,01_Base!$F$2:$F$1201,$W$7) -> 1200
B15: O volume está pressionando a capacidade? | K15: Em qual canal o SLA está abaixo da meta? | V15: Resolvidos | W15: =COUNTIFS(01_Base!$B$2:$B$1201,">="&$W$8,01_Base!$B$2:$B$1201,"<="&$W$9,01_Base!$C$2:$C$1201,$W$5,01_Base!$D$2:$D$1201,$W$6,01_Base!$F$2:$F$1201,$W$7,01_Base!$G$2:$G$1201,"Resolvido") -> 1162
B16: =IF($W$14=0,"Sem atendimentos com esses filtros.","Média de "&ROUND($W$27,1)&" atendimentos por dia útil, "&ROUND($W$28*100,0)&"% da capacidade estimada de "&ROUND($W$26,0)&" por dia. A semana de maior volume começa em "&DAY(INDEX($V$54:$V$62,MATCH(MAX($W$54:$W$62),$W$54:$W$62,0)))&"/"&MONTH(INDEX($V$54:$V$62,MATCH(MAX($W$54:$W$62),$W$54:$W$62,0)))&" ("&MAX($W$54:$W$62)&" atendimentos).") -> Média de 27.3 atendimentos por dia útil, 97% da capacidade estimada de 28 por dia. A semana de maior volume começa em 12/10 (166 atendimentos). | K16: =IF($W$17=0,"Sem dados de SLA com esses filtros.","SLA geral de "&ROUND($W$19*100,1)&"%, contra meta de "&ROUND(02_Parâmetros!$B$7*100,0)&"%. O canal com menor SLA é "&INDEX($V$32:$V$35,MATCH(MIN($Y$32:$Y$35),$Y$32:$Y$35,0))&" ("&ROUND(MIN($Y$32:$Y$35)*100,1)&"%).") -> SLA geral de 88.1%, contra meta de 92%. O canal com menor SLA é E-mail (82.2%). | V16: TMA (min) | W16: =IFERROR(AVERAGEIFS(01_Base!$I$2:$I$1201,01_Base!$B$2:$B$1201,">="&$W$8,01_Base!$B$2:$B$1201,"<="&$W$9,01_Base!$C$2:$C$1201,$W$5,01_Base!$D$2:$D$1201,$W$6,01_Base!$F$2:$F$1201,$W$7,01_Base!$G$2:$G$1201,"Resolvido"),0) -> 9.527883
V17: SLA elegíveis | W17: =COUNTIFS(01_Base!$B$2:$B$1201,">="&$W$8,01_Base!$B$2:$B$1201,"<="&$W$9,01_Base!$C$2:$C$1201,$W$5,01_Base!$D$2:$D$1201,$W$6,01_Base!$F$2:$F$1201,$W$7,01_Base!$N$2:$N$1201,"Sim")+COUNTIFS(01_Base!$B$2:$B$1201,">="&$W$8,01_Base!$B$2:$B$1201,"<="&$W$9,01_Base!$C$2:$C$1201,$W$5,01_Base!$D$2:$D$1201,$W$6,01_Base!$F$2:$F$1201,$W$7,01_Base!$N$2:$N$1201,"Não") -> 1164
V18: SLA dentro do prazo | W18: =COUNTIFS(01_Base!$B$2:$B$1201,">="&$W$8,01_Base!$B$2:$B$1201,"<="&$W$9,01_Base!$C$2:$C$1201,$W$5,01_Base!$D$2:$D$1201,$W$6,01_Base!$F$2:$F$1201,$W$7,01_Base!$N$2:$N$1201,"Sim") -> 1026
V19: SLA % | W19: =IF(W17=0,0,W18/W17) -> 0.8814433
V20: CSAT respostas | W20: =COUNTIFS(01_Base!$B$2:$B$1201,">="&$W$8,01_Base!$B$2:$B$1201,"<="&$W$9,01_Base!$C$2:$C$1201,$W$5,01_Base!$D$2:$D$1201,$W$6,01_Base!$F$2:$F$1201,$W$7,01_Base!$K$2:$K$1201,">=1") -> 430
V21: CSAT satisfeitas | W21: =COUNTIFS(01_Base!$B$2:$B$1201,">="&$W$8,01_Base!$B$2:$B$1201,"<="&$W$9,01_Base!$C$2:$C$1201,$W$5,01_Base!$D$2:$D$1201,$W$6,01_Base!$F$2:$F$1201,$W$7,01_Base!$K$2:$K$1201,">=4") -> 348
V22: CSAT % | W22: =IF(W20=0,0,W21/W20) -> 0.80930233
V23: FCR resolvidos no 1º contato | W23: =COUNTIFS(01_Base!$B$2:$B$1201,">="&$W$8,01_Base!$B$2:$B$1201,"<="&$W$9,01_Base!$C$2:$C$1201,$W$5,01_Base!$D$2:$D$1201,$W$6,01_Base!$F$2:$F$1201,$W$7,01_Base!$G$2:$G$1201,"Resolvido",01_Base!$J$2:$J$1201,"Sim") -> 880
V24: FCR % | W24: =IF(W15=0,0,W23/W15) -> 0.75731497
V25: Produtividade | W25: =IF(OR(W10=0,W11=0),0,W15/(W10*W11)) -> 3.3011364
V26: Capacidade diária | W26: =W10*02_Parâmetros!$B$8 -> 28
V27: Volume médio por dia útil | W27: =IF(W11=0,0,W14/W11) -> 27.272727
V28: Utilização da capacidade | W28: =IF(W26=0,0,W27/W26) -> 0.97402597
V31: SLA por canal | W31: Elegíveis | X31: Dentro | Y31: SLA % | Z31: Meta
V32: =02_Parâmetros!$A$14 -> WhatsApp | W32: =COUNTIFS(01_Base!$B$2:$B$1201,">="&$W$8,01_Base!$B$2:$B$1201,"<="&$W$9,01_Base!$C$2:$C$1201,$V32,01_Base!$D$2:$D$1201,$W$6,01_Base!$F$2:$F$1201,$W$7,01_Base!$N$2:$N$1201,"Sim")+COUNTIFS(01_Base!$B$2:$B$1201,">="&$W$8,01_Base!$B$2:$B$1201,"<="&$W$9,01_Base!$C$2:$C$1201,$V32,01_Base!$D$2:$D$1201,$W$6,01_Base!$F$2:$F$1201,$W$7,01_Base!$N$2:$N$1201,"Não") -> 428 | X32: =COUNTIFS(01_Base!$B$2:$B$1201,">="&$W$8,01_Base!$B$2:$B$1201,"<="&$W$9,01_Base!$C$2:$C$1201,$V32,01_Base!$D$2:$D$1201,$W$6,01_Base!$F$2:$F$1201,$W$7,01_Base!$N$2:$N$1201,"Sim") -> 384 | Y32: =IF(W32=0,"",X32/W32) -> 0.89719626 | Z32: =02_Parâmetros!$B$7 -> 0.92
B33: Quais motivos derrubam o CSAT? | K33: A carga está bem distribuída entre as equipes? | V33: =02_Parâmetros!$A$15 -> Chat | W33: =COUNTIFS(01_Base!$B$2:$B$1201,">="&$W$8,01_Base!$B$2:$B$1201,"<="&$W$9,01_Base!$C$2:$C$1201,$V33,01_Base!$D$2:$D$1201,$W$6,01_Base!$F$2:$F$1201,$W$7,01_Base!$N$2:$N$1201,"Sim")+COUNTIFS(01_Base!$B$2:$B$1201,">="&$W$8,01_Base!$B$2:$B$1201,"<="&$W$9,01_Base!$C$2:$C$1201,$V33,01_Base!$D$2:$D$1201,$W$6,01_Base!$F$2:$F$1201,$W$7,01_Base!$N$2:$N$1201,"Não") -> 262 | X33: =COUNTIFS(01_Base!$B$2:$B$1201,">="&$W$8,01_Base!$B$2:$B$1201,"<="&$W$9,01_Base!$C$2:$C$1201,$V33,01_Base!$D$2:$D$1201,$W$6,01_Base!$F$2:$F$1201,$W$7,01_Base!$N$2:$N$1201,"Sim") -> 243 | Y33: =IF(W33=0,"",X33/W33) -> 0.92748092 | Z33: =02_Parâmetros!$B$7 -> 0.92
B34: =IF($W$20=0,"Sem respostas de CSAT com esses filtros.","O menor CSAT está em "&INDEX($V$39:$V$44,MATCH(MIN($Y$39:$Y$44),$Y$39:$Y$44,0))&" ("&ROUND(MIN($Y$39:$Y$44)*100,1)&"%, "&INDEX($W$39:$W$44,MATCH(MIN($Y$39:$Y$44),$Y$39:$Y$44,0))&" respostas). O maior é "&INDEX($V$39:$V$44,MATCH(MAX($Y$39:$Y$44),$Y$39:$Y$44,0))&" ("&ROUND(MAX($Y$39:$Y$44)*100,1)&"%). A meta de CSAT é "&ROUND(02_Parâmetros!$B$9*100,0)&"%.") -> O menor CSAT está em Atraso na entrega (72.4%, 116 respostas). O maior é Dúvida sobre o pedido (90.6%). A meta de CSAT é 85%. | K34: =IF($W$15=0,"Sem resolvidos com esses filtros.","A equipe com maior carga é "&INDEX($V$48:$V$50,MATCH(MAX($Y$48:$Y$50),$Y$48:$Y$50,0))&" ("&ROUND(MAX($Y$48:$Y$50),2)&" resolvidos por atendente por dia útil) e a de menor carga é "&INDEX($V$48:$V$50,MATCH(MIN($Y$48:$Y$50),$Y$48:$Y$50,0))&" ("&ROUND(MIN($Y$48:$Y$50),2)&"). Meta: "&ROUND(02_Parâmetros!$B$8,1)&".") -> A equipe com maior carga é Equipe C (3.89 resolvidos por atendente por dia útil) e a de menor carga é Equipe B (3.1). Meta: 3.5. | V34: =02_Parâmetros!$A$16 -> E-mail | W34: =COUNTIFS(01_Base!$B$2:$B$1201,">="&$W$8,01_Base!$B$2:$B$1201,"<="&$W$9,01_Base!$C$2:$C$1201,$V34,01_Base!$D$2:$D$1201,$W$6,01_Base!$F$2:$F$1201,$W$7,01_Base!$N$2:$N$1201,"Sim")+COUNTIFS(01_Base!$B$2:$B$1201,">="&$W$8,01_Base!$B$2:$B$1201,"<="&$W$9,01_Base!$C$2:$C$1201,$V34,01_Base!$D$2:$D$1201,$W$6,01_Base!$F$2:$F$1201,$W$7,01_Base!$N$2:$N$1201,"Não") -> 297 | X34: =COUNTIFS(01_Base!$B$2:$B$1201,">="&$W$8,01_Base!$B$2:$B$1201,"<="&$W$9,01_Base!$C$2:$C$1201,$V34,01_Base!$D$2:$D$1201,$W$6,01_Base!$F$2:$F$1201,$W$7,01_Base!$N$2:$N$1201,"Sim") -> 244 | Y34: =IF(W34=0,"",X34/W34) -> 0.82154882 | Z34: =02_Parâmetros!$B$7 -> 0.92
V35: =02_Parâmetros!$A$17 -> Telefone | W35: =COUNTIFS(01_Base!$B$2:$B$1201,">="&$W$8,01_Base!$B$2:$B$1201,"<="&$W$9,01_Base!$C$2:$C$1201,$V35,01_Base!$D$2:$D$1201,$W$6,01_Base!$F$2:$F$1201,$W$7,01_Base!$N$2:$N$1201,"Sim")+COUNTIFS(01_Base!$B$2:$B$1201,">="&$W$8,01_Base!$B$2:$B$1201,"<="&$W$9,01_Base!$C$2:$C$1201,$V35,01_Base!$D$2:$D$1201,$W$6,01_Base!$F$2:$F$1201,$W$7,01_Base!$N$2:$N$1201,"Não") -> 177 | X35: =COUNTIFS(01_Base!$B$2:$B$1201,">="&$W$8,01_Base!$B$2:$B$1201,"<="&$W$9,01_Base!$C$2:$C$1201,$V35,01_Base!$D$2:$D$1201,$W$6,01_Base!$F$2:$F$1201,$W$7,01_Base!$N$2:$N$1201,"Sim") -> 155 | Y35: =IF(W35=0,"",X35/W35) -> 0.87570621 | Z35: =02_Parâmetros!$B$7 -> 0.92
V38: CSAT por motivo | W38: Respostas | X38: Satisfeitas | Y38: CSAT % | Z38: FCR resolvidos | AA38: FCR sim | AB38: FCR %
V39: =02_Parâmetros!$A$37 -> Atraso na entrega | W39: =COUNTIFS(01_Base!$B$2:$B$1201,">="&$W$8,01_Base!$B$2:$B$1201,"<="&$W$9,01_Base!$C$2:$C$1201,$W$5,01_Base!$D$2:$D$1201,$W$6,01_Base!$F$2:$F$1201,$V39,01_Base!$K$2:$K$1201,">=1") -> 116 | X39: =COUNTIFS(01_Base!$B$2:$B$1201,">="&$W$8,01_Base!$B$2:$B$1201,"<="&$W$9,01_Base!$C$2:$C$1201,$W$5,01_Base!$D$2:$D$1201,$W$6,01_Base!$F$2:$F$1201,$V39,01_Base!$K$2:$K$1201,">=4") -> 84 | Y39: =IF(W39=0,"",X39/W39) -> 0.72413793 | Z39: =COUNTIFS(01_Base!$B$2:$B$1201,">="&$W$8,01_Base!$B$2:$B$1201,"<="&$W$9,01_Base!$C$2:$C$1201,$W$5,01_Base!$D$2:$D$1201,$W$6,01_Base!$F$2:$F$1201,$V39,01_Base!$G$2:$G$1201,"Resolvido") -> 321 | AA39: =COUNTIFS(01_Base!$B$2:$B$1201,">="&$W$8,01_Base!$B$2:$B$1201,"<="&$W$9,01_Base!$C$2:$C$1201,$W$5,01_Base!$D$2:$D$1201,$W$6,01_Base!$F$2:$F$1201,$V39,01_Base!$G$2:$G$1201,"Resolvido",01_Base!$J$2:$J$1201,"Sim") -> 214 | AB39: =IF(Z39=0,"",AA39/Z39) -> 0.66666667
V40: =02_Parâmetros!$A$38 -> Cobrança ou pagamento | W40: =COUNTIFS(01_Base!$B$2:$B$1201,">="&$W$8,01_Base!$B$2:$B$1201,"<="&$W$9,01_Base!$C$2:$C$1201,$W$5,01_Base!$D$2:$D$1201,$W$6,01_Base!$F$2:$F$1201,$V40,01_Base!$K$2:$K$1201,">=1") -> 74 | X40: =COUNTIFS(01_Base!$B$2:$B$1201,">="&$W$8,01_Base!$B$2:$B$1201,"<="&$W$9,01_Base!$C$2:$C$1201,$W$5,01_Base!$D$2:$D$1201,$W$6,01_Base!$F$2:$F$1201,$V40,01_Base!$K$2:$K$1201,">=4") -> 55 | Y40: =IF(W40=0,"",X40/W40) -> 0.74324324 | Z40: =COUNTIFS(01_Base!$B$2:$B$1201,">="&$W$8,01_Base!$B$2:$B$1201,"<="&$W$9,01_Base!$C$2:$C$1201,$W$5,01_Base!$D$2:$D$1201,$W$6,01_Base!$F$2:$F$1201,$V40,01_Base!$G$2:$G$1201,"Resolvido") -> 223 | AA40: =COUNTIFS(01_Base!$B$2:$B$1201,">="&$W$8,01_Base!$B$2:$B$1201,"<="&$W$9,01_Base!$C$2:$C$1201,$W$5,01_Base!$D$2:$D$1201,$W$6,01_Base!$F$2:$F$1201,$V40,01_Base!$G$2:$G$1201,"Resolvido",01_Base!$J$2:$J$1201,"Sim") -> 168 | AB40: =IF(Z40=0,"",AA40/Z40) -> 0.75336323
V41: =02_Parâmetros!$A$39 -> Produto incorreto ou avariado | W41: =COUNTIFS(01_Base!$B$2:$B$1201,">="&$W$8,01_Base!$B$2:$B$1201,"<="&$W$9,01_Base!$C$2:$C$1201,$W$5,01_Base!$D$2:$D$1201,$W$6,01_Base!$F$2:$F$1201,$V41,01_Base!$K$2:$K$1201,">=1") -> 68 | X41: =COUNTIFS(01_Base!$B$2:$B$1201,">="&$W$8,01_Base!$B$2:$B$1201,"<="&$W$9,01_Base!$C$2:$C$1201,$W$5,01_Base!$D$2:$D$1201,$W$6,01_Base!$F$2:$F$1201,$V41,01_Base!$K$2:$K$1201,">=4") -> 56 | Y41: =IF(W41=0,"",X41/W41) -> 0.82352941 | Z41: =COUNTIFS(01_Base!$B$2:$B$1201,">="&$W$8,01_Base!$B$2:$B$1201,"<="&$W$9,01_Base!$C$2:$C$1201,$W$5,01_Base!$D$2:$D$1201,$W$6,01_Base!$F$2:$F$1201,$V41,01_Base!$G$2:$G$1201,"Resolvido") -> 179 | AA41: =COUNTIFS(01_Base!$B$2:$B$1201,">="&$W$8,01_Base!$B$2:$B$1201,"<="&$W$9,01_Base!$C$2:$C$1201,$W$5,01_Base!$D$2:$D$1201,$W$6,01_Base!$F$2:$F$1201,$V41,01_Base!$G$2:$G$1201,"Resolvido",01_Base!$J$2:$J$1201,"Sim") -> 125 | AB41: =IF(Z41=0,"",AA41/Z41) -> 0.69832402
V42: =02_Parâmetros!$A$40 -> Dúvida sobre o pedido | W42: =COUNTIFS(01_Base!$B$2:$B$1201,">="&$W$8,01_Base!$B$2:$B$1201,"<="&$W$9,01_Base!$C$2:$C$1201,$W$5,01_Base!$D$2:$D$1201,$W$6,01_Base!$F$2:$F$1201,$V42,01_Base!$K$2:$K$1201,">=1") -> 85 | X42: =COUNTIFS(01_Base!$B$2:$B$1201,">="&$W$8,01_Base!$B$2:$B$1201,"<="&$W$9,01_Base!$C$2:$C$1201,$W$5,01_Base!$D$2:$D$1201,$W$6,01_Base!$F$2:$F$1201,$V42,01_Base!$K$2:$K$1201,">=4") -> 77 | Y42: =IF(W42=0,"",X42/W42) -> 0.90588235 | Z42: =COUNTIFS(01_Base!$B$2:$B$1201,">="&$W$8,01_Base!$B$2:$B$1201,"<="&$W$9,01_Base!$C$2:$C$1201,$W$5,01_Base!$D$2:$D$1201,$W$6,01_Base!$F$2:$F$1201,$V42,01_Base!$G$2:$G$1201,"Resolvido") -> 218 | AA42: =COUNTIFS(01_Base!$B$2:$B$1201,">="&$W$8,01_Base!$B$2:$B$1201,"<="&$W$9,01_Base!$C$2:$C$1201,$W$5,01_Base!$D$2:$D$1201,$W$6,01_Base!$F$2:$F$1201,$V42,01_Base!$G$2:$G$1201,"Resolvido",01_Base!$J$2:$J$1201,"Sim") -> 182 | AB42: =IF(Z42=0,"",AA42/Z42) -> 0.83486239
V43: =02_Parâmetros!$A$41 -> Cancelamento | W43: =COUNTIFS(01_Base!$B$2:$B$1201,">="&$W$8,01_Base!$B$2:$B$1201,"<="&$W$9,01_Base!$C$2:$C$1201,$W$5,01_Base!$D$2:$D$1201,$W$6,01_Base!$F$2:$F$1201,$V43,01_Base!$K$2:$K$1201,">=1") -> 51 | X43: =COUNTIFS(01_Base!$B$2:$B$1201,">="&$W$8,01_Base!$B$2:$B$1201,"<="&$W$9,01_Base!$C$2:$C$1201,$W$5,01_Base!$D$2:$D$1201,$W$6,01_Base!$F$2:$F$1201,$V43,01_Base!$K$2:$K$1201,">=4") -> 44 | Y43: =IF(W43=0,"",X43/W43) -> 0.8627451 | Z43: =COUNTIFS(01_Base!$B$2:$B$1201,">="&$W$8,01_Base!$B$2:$B$1201,"<="&$W$9,01_Base!$C$2:$C$1201,$W$5,01_Base!$D$2:$D$1201,$W$6,01_Base!$F$2:$F$1201,$V43,01_Base!$G$2:$G$1201,"Resolvido") -> 114 | AA43: =COUNTIFS(01_Base!$B$2:$B$1201,">="&$W$8,01_Base!$B$2:$B$1201,"<="&$W$9,01_Base!$C$2:$C$1201,$W$5,01_Base!$D$2:$D$1201,$W$6,01_Base!$F$2:$F$1201,$V43,01_Base!$G$2:$G$1201,"Resolvido",01_Base!$J$2:$J$1201,"Sim") -> 96 | AB43: =IF(Z43=0,"",AA43/Z43) -> 0.84210526
V44: =02_Parâmetros!$A$42 -> Cadastro ou acesso | W44: =COUNTIFS(01_Base!$B$2:$B$1201,">="&$W$8,01_Base!$B$2:$B$1201,"<="&$W$9,01_Base!$C$2:$C$1201,$W$5,01_Base!$D$2:$D$1201,$W$6,01_Base!$F$2:$F$1201,$V44,01_Base!$K$2:$K$1201,">=1") -> 36 | X44: =COUNTIFS(01_Base!$B$2:$B$1201,">="&$W$8,01_Base!$B$2:$B$1201,"<="&$W$9,01_Base!$C$2:$C$1201,$W$5,01_Base!$D$2:$D$1201,$W$6,01_Base!$F$2:$F$1201,$V44,01_Base!$K$2:$K$1201,">=4") -> 32 | Y44: =IF(W44=0,"",X44/W44) -> 0.88888889 | Z44: =COUNTIFS(01_Base!$B$2:$B$1201,">="&$W$8,01_Base!$B$2:$B$1201,"<="&$W$9,01_Base!$C$2:$C$1201,$W$5,01_Base!$D$2:$D$1201,$W$6,01_Base!$F$2:$F$1201,$V44,01_Base!$G$2:$G$1201,"Resolvido") -> 107 | AA44: =COUNTIFS(01_Base!$B$2:$B$1201,">="&$W$8,01_Base!$B$2:$B$1201,"<="&$W$9,01_Base!$C$2:$C$1201,$W$5,01_Base!$D$2:$D$1201,$W$6,01_Base!$F$2:$F$1201,$V44,01_Base!$G$2:$G$1201,"Resolvido",01_Base!$J$2:$J$1201,"Sim") -> 95 | AB44: =IF(Z44=0,"",AA44/Z44) -> 0.88785047
V47: Produtividade por equipe | W47: Resolvidos | X47: Atendentes | Y47: Produtividade | Z47: Meta | AA47: CSAT respostas | AB47: CSAT satisfeitas | AC47: CSAT %
V48: =02_Parâmetros!$A$32 -> Equipe A | W48: =COUNTIFS(01_Base!$B$2:$B$1201,">="&$W$8,01_Base!$B$2:$B$1201,"<="&$W$9,01_Base!$C$2:$C$1201,$W$5,01_Base!$D$2:$D$1201,$V48,01_Base!$F$2:$F$1201,$W$7,01_Base!$G$2:$G$1201,"Resolvido") -> 411 | X48: =COUNTIF(02_Parâmetros!$B$21:$B$28,V48) -> 3 | Y48: =IF(OR(X48=0,$W$11=0),0,W48/(X48*$W$11)) -> 3.1136364 | Z48: =02_Parâmetros!$B$8 -> 3.5 | AA48: =COUNTIFS(01_Base!$B$2:$B$1201,">="&$W$8,01_Base!$B$2:$B$1201,"<="&$W$9,01_Base!$C$2:$C$1201,$W$5,01_Base!$D$2:$D$1201,$V48,01_Base!$F$2:$F$1201,$W$7,01_Base!$K$2:$K$1201,">=1") -> 136 | AB48: =COUNTIFS(01_Base!$B$2:$B$1201,">="&$W$8,01_Base!$B$2:$B$1201,"<="&$W$9,01_Base!$C$2:$C$1201,$W$5,01_Base!$D$2:$D$1201,$V48,01_Base!$F$2:$F$1201,$W$7,01_Base!$K$2:$K$1201,">=4") -> 119 | AC48: =IF(AA48=0,"",AB48/AA48) -> 0.875
...

Sheet 04_Validacao
A1: Validação das fórmulas e da base
A2: Cada teste compara um resultado com o esperado. A situação deve ser OK em todos os testes.
A3: =IF(COUNTIF(E6:E40,"Divergente")=0,"Todos os testes passaram","Há testes divergentes: revisar") -> Todos os testes passaram
A5: Teste | B5: Resultado | C5: Esperado | D5: Observação | E5: Situação
A6: Linhas na base | B6: =COUNTA(01_Base!$A$2:$A$1201) -> 1200 | C6: 1200 | D6: 1.200 atendimentos sintéticos | E6: =IF(B6=C6,"OK","Divergente") -> OK
A7: IDs duplicados | B7: =SUMPRODUCT(--(COUNTIF(01_Base!$A$2:$A$1201,01_Base!$A$2:$A$1201)>1)) -> 0 | C7: 0 | E7: =IF(B7=C7,"OK","Divergente") -> OK
A8: Aberturas fora de 01/09/2026 a 30/10/2026 | B8: =COUNTIFS(01_Base!$B$2:$B$1201,"<"&DATE(2026,9,1))+COUNTIFS(01_Base!$B$2:$B$1201,">"&DATE(2026,10,30)) -> 0 | C8: 0 | D8: Período previsto da base | E8: =IF(B8=C8,"OK","Divergente") -> OK
A9: Campos obrigatórios em branco | B9: =COUNTBLANK(01_Base!$A$2:$G$1201) -> 0 | C9: 0 | D9: ID, data, canal, equipe, atendente, motivo e status | E9: =IF(B9=C9,"OK","Divergente") -> OK
A10: Canal fora da lista | B10: =SUMPRODUCT(--(COUNTIF(02_Parâmetros!$A$14:$A$17,01_Base!$C$2:$C$1201)=0)) -> 0 | C10: 0 | E10: =IF(B10=C10,"OK","Divergente") -> OK
A11: Equipe fora da lista | B11: =SUMPRODUCT(--(COUNTIF(02_Parâmetros!$A$32:$A$34,01_Base!$D$2:$D$1201)=0)) -> 0 | C11: 0 | E11: =IF(B11=C11,"OK","Divergente") -> OK
A12: Motivo fora da lista | B12: =SUMPRODUCT(--(COUNTIF(02_Parâmetros!$A$37:$A$42,01_Base!$F$2:$F$1201)=0)) -> 0 | C12: 0 | E12: =IF(B12=C12,"OK","Divergente") -> OK
A13: Status diferente de Resolvido ou Pendente | B13: =SUMPRODUCT((01_Base!$G$2:$G$1201<>"Resolvido")*(01_Base!$G$2:$G$1201<>"Pendente")) -> 0 | C13: 0 | E13: =IF(B13=C13,"OK","Divergente") -> OK
A14: Atendente com equipe diferente do cadastro | B14: =SUMPRODUCT(--(COUNTIFS(02_Parâmetros!$A$21:$A$28,01_Base!$E$2:$E$1201,02_Parâmetros!$B$21:$B$28,01_Base!$D$2:$D$1201)=0)) -> 0 | C14: 0 | E14: =IF(B14=C14,"OK","Divergente") -> OK
A15: Notas fora de 1 a 5 | B15: =COUNTIFS(01_Base!$K$2:$K$1201,"<1")+COUNTIFS(01_Base!$K$2:$K$1201,">5") -> 0 | C15: 0 | E15: =IF(B15=C15,"OK","Divergente") -> OK
A16: Resolvidos com tempo de atendimento menor ou igual a 0 | B16: =COUNTIFS(01_Base!$G$2:$G$1201,"Resolvido",01_Base!$I$2:$I$1201,"<=0") -> 0 | C16: 0 | E16: =IF(B16=C16,"OK","Divergente") -> OK
A17: Pendentes com FCR preenchido | B17: =COUNTIFS(01_Base!$G$2:$G$1201,"Pendente",01_Base!$J$2:$J$1201,"<>") -> 0 | C17: 0 | D17: FCR só vale para resolvidos | E17: =IF(B17=C17,"OK","Divergente") -> OK
A18: Resolvidos sem FCR preenchido | B18: =COUNTIFS(01_Base!$G$2:$G$1201,"Resolvido",01_Base!$J$2:$J$1201,"") -> 0 | C18: 0 | E18: =IF(B18=C18,"OK","Divergente") -> OK
A20: Conferência dos seis indicadores, recalculados por outro caminho (SUMPRODUCT), com os filtros atuais do dashboard
A21: Indicador | B21: Dashboard | C21: Recalculado | D21: Diferença | E21: Situação
A22: Volume | B22: =03_Dashboard!$W$14 -> 1200 | C22: =IFERROR(SUMPRODUCT((((01_Base!$C$2:$C$1201=03_Dashboard!$G$6)+(03_Dashboard!$G$6="Todos"))>0)*(((01_Base!$D$2:$D$1201=03_Dashboard!$K$6)+(03_Dashboard!$K$6="Todos"))>0)*(((01_Base!$F$2:$F$1201=03_Dashboard!$O$6)+(03_Dashboard!$O$6="Todos"))>0)*(01_Base!$B$2:$B$1201>=03_Dashboard!$B$6)*(01_Base!$B$2:$B$1201<=03_Dashboard!$D$6)),"n/d") -> 1200 | D22: =IFERROR(B22-C22,"n/d") -> 0 | E22: =IF(ISNUMBER(D22),IF(ABS(D22)<0.000000001,"OK","Divergente"),"OK") -> OK
A23: TMA (min) | B23: =03_Dashboard!$W$16 -> 9.527883 | C23: =IFERROR(SUMPRODUCT((((01_Base!$C$2:$C$1201=03_Dashboard!$G$6)+(03_Dashboard!$G$6="Todos"))>0)*(((01_Base!$D$2:$D$1201=03_Dashboard!$K$6)+(03_Dashboard!$K$6="Todos"))>0)*(((01_Base!$F$2:$F$1201=03_Dashboard!$O$6)+(03_Dashboard!$O$6="Todos"))>0)*(01_Base!$B$2:$B$1201>=03_Dashboard!$B$6)*(01_Base!$B$2:$B$1201<=03_Dashboard!$D$6)*(01_Base!$G$2:$G$1201="Resolvido")*01_Base!$I$2:$I$1201)/SUMPRODUCT((((01_Base!$C$2:$C$1201=03_Dashboard!$G$6)+(03_Dashboard!$G$6="Todos"))>0)*(((01_Base!$D$2:$D$1201=03_Dashboard!$K$6)+(03_Dashboard!$K$6="Todos"))>0)*(((01_Base!$F$2:$F$1201=03_Dashboard!$O$6)+(03_Dashboard!$O$6="Todos"))>0)*(01_Base!$B$2:$B$1201>=03_Dashboard!$B$6)*(01_Base!$B$2:$B$1201<=03_Dashboard!$D$6)*(01_Base!$G$2:$G$1201="Resolvido")),"n/d") -> 9.527883 | D23: =IFERROR(B23-C23,"n/d") -> 0 | E23: =IF(ISNUMBER(D23),IF(ABS(D23)<0.000000001,"OK","Divergente"),"OK") -> OK
A24: SLA de 1ª resposta | B24: =03_Dashboard!$W$19 -> 0.8814433 | C24: =IFERROR(SUMPRODUCT((((01_Base!$C$2:$C$1201=03_Dashboard!$G$6)+(03_Dashboard!$G$6="Todos"))>0)*(((01_Base!$D$2:$D$1201=03_Dashboard!$K$6)+(03_Dashboard!$K$6="Todos"))>0)*(((01_Base!$F$2:$F$1201=03_Dashboard!$O$6)+(03_Dashboard!$O$6="Todos"))>0)*(01_Base!$B$2:$B$1201>=03_Dashboard!$B$6)*(01_Base!$B$2:$B$1201<=03_Dashboard!$D$6)*(01_Base!$N$2:$N$1201="Sim"))/SUMPRODUCT((((01_Base!$C$2:$C$1201=03_Dashboard!$G$6)+(03_Dashboard!$G$6="Todos"))>0)*(((01_Base!$D$2:$D$1201=03_Dashboard!$K$6)+(03_Dashboard!$K$6="Todos"))>0)*(((01_Base!$F$2:$F$1201=03_Dashboard!$O$6)+(03_Dashboard!$O$6="Todos"))>0)*(01_Base!$B$2:$B$1201>=03_Dashboard!$B$6)*(01_Base!$B$2:$B$1201<=03_Dashboard!$D$6)*(01_Base!$N$2:$N$1201<>"")),"n/d") -> 0.8814433 | D24: =IFERROR(B24-C24,"n/d") -> 0 | E24: =IF(ISNUMBER(D24),IF(ABS(D24)<0.000000001,"OK","Divergente"),"OK") -> OK
A25: Produtividade | B25: =03_Dashboard!$W$25 -> 3.3011364 | C25: =IFERROR(SUMPRODUCT((((01_Base!$C$2:$C$1201=03_Dashboard!$G$6)+(03_Dashboard!$G$6="Todos"))>0)*(((01_Base!$D$2:$D$1201=03_Dashboard!$K$6)+(03_Dashboard!$K$6="Todos"))>0)*(((01_Base!$F$2:$F$1201=03_Dashboard!$O$6)+(03_Dashboard!$O$6="Todos"))>0)*(01_Base!$B$2:$B$1201>=03_Dashboard!$B$6)*(01_Base!$B$2:$B$1201<=03_Dashboard!$D$6)*(01_Base!$G$2:$G$1201="Resolvido"))/(IF(03_Dashboard!$K$6="Todos",ROWS(02_Parâmetros!$A$21:$A$28),SUMPRODUCT(--(02_Parâmetros!$B$21:$B$28=03_Dashboard!$K$6)))*NETWORKDAYS(03_Dashboard!$B$6,03_Dashboard!$D$6)),"n/d") -> 3.3011364 | D25: =IFERROR(B25-C25,"n/d") -> 0 | E25: =IF(ISNUMBER(D25),IF(ABS(D25)<0.000000001,"OK","Divergente"),"OK") -> OK
A26: CSAT | B26: =03_Dashboard!$W$22 -> 0.80930233 | C26: =IFERROR(SUMPRODUCT((((01_Base!$C$2:$C$1201=03_Dashboard!$G$6)+(03_Dashboard!$G$6="Todos"))>0)*(((01_Base!$D$2:$D$1201=03_Dashboard!$K$6)+(03_Dashboard!$K$6="Todos"))>0)*(((01_Base!$F$2:$F$1201=03_Dashboard!$O$6)+(03_Dashboard!$O$6="Todos"))>0)*(01_Base!$B$2:$B$1201>=03_Dashboard!$B$6)*(01_Base!$B$2:$B$1201<=03_Dashboard!$D$6)*(01_Base!$K$2:$K$1201>=4))/SUMPRODUCT((((01_Base!$C$2:$C$1201=03_Dashboard!$G$6)+(03_Dashboard!$G$6="Todos"))>0)*(((01_Base!$D$2:$D$1201=03_Dashboard!$K$6)+(03_Dashboard!$K$6="Todos"))>0)*(((01_Base!$F$2:$F$1201=03_Dashboard!$O$6)+(03_Dashboard!$O$6="Todos"))>0)*(01_Base!$B$2:$B$1201>=03_Dashboard!$B$6)*(01_Base!$B$2:$B$1201<=03_Dashboard!$D$6)*(01_Base!$K$2:$K$1201<>"")),"n/d") -> 0.80930233 | D26: =IFERROR(B26-C26,"n/d") -> 0 | E26: =IF(ISNUMBER(D26),IF(ABS(D26)<0.000000001,"OK","Divergente"),"OK") -> OK
A27: FCR | B27: =03_Dashboard!$W$24 -> 0.75731497 | C27: =IFERROR(SUMPRODUCT((((01_Base!$C$2:$C$1201=03_Dashboard!$G$6)+(03_Dashboard!$G$6="Todos"))>0)*(((01_Base!$D$2:$D$1201=03_Dashboard!$K$6)+(03_Dashboard!$K$6="Todos"))>0)*(((01_Base!$F$2:$F$1201=03_Dashboard!$O$6)+(03_Dashboard!$O$6="Todos"))>0)*(01_Base!$B$2:$B$1201>=03_Dashboard!$B$6)*(01_Base!$B$2:$B$1201<=03_Dashboard!$D$6)*(01_Base!$G$2:$G$1201="Resolvido")*(01_Base!$J$2:$J$1201="Sim"))/SUMPRODUCT((((01_Base!$C$2:$C$1201=03_Dashboard!$G$6)+(03_Dashboard!$G$6="Todos"))>0)*(((01_Base!$D$2:$D$1201=03_Dashboard!$K$6)+(03_Dashboard!$K$6="Todos"))>0)*(((01_Base!$F$2:$F$1201=03_Dashboard!$O$6)+(03_Dashboard!$O$6="Todos"))>0)*(01_Base!$B$2:$B$1201>=03_Dashboard!$B$6)*(01_Base!$B$2:$B$1201<=03_Dashboard!$D$6)*(01_Base!$G$2:$G$1201="Resolvido")),"n/d") -> 0.75731497 | D27: =IFERROR(B27-C27,"n/d") -> 0 | E27: =IF(ISNUMBER(D27),IF(ABS(D27)<0.000000001,"OK","Divergente"),"OK") -> OK
A29: Referência independente (calculada fora do Excel, com pandas, para a base completa e filtros em Todos)
A30: Indicador | B30: Dashboard | C30: Esperado (pandas) | D30: Observação | E30: Situação
A31: Volume | B31: =03_Dashboard!$W$14 -> 1200 | C31: 1200 | D31: Só se aplica com filtros em Todos e período completo | E31: =IF(AND(03_Dashboard!$G$6="Todos",03_Dashboard!$K$6="Todos",03_Dashboard!$O$6="Todos",03_Dashboard!$B$6=02_Parâmetros!$B$46,03_Dashboard!$D$6=02_Parâmetros!$B$47),IF(ROUND(B31,0)=C31,"OK","Divergente"),"OK") -> OK
A32: TMA (min) | B32: =03_Dashboard!$W$16 -> 9.527883 | C32: 9.5279 | D32: Só se aplica com filtros em Todos e período completo | E32: =IF(AND(03_Dashboard!$G$6="Todos",03_Dashboard!$K$6="Todos",03_Dashboard!$O$6="Todos",03_Dashboard!$B$6=02_Parâmetros!$B$46,03_Dashboard!$D$6=02_Parâmetros!$B$47),IF(ROUND(B32,4)=C32,"OK","Divergente"),"OK") -> OK
A33: SLA de 1ª resposta | B33: =03_Dashboard!$W$19 -> 0.8814433 | C33: 0.8814 | D33: Só se aplica com filtros em Todos e período completo | E33: =IF(AND(03_Dashboard!$G$6="Todos",03_Dashboard!$K$6="Todos",03_Dashboard!$O$6="Todos",03_Dashboard!$B$6=02_Parâmetros!$B$46,03_Dashboard!$D$6=02_Parâmetros!$B$47),IF(ROUND(B33,4)=C33,"OK","Divergente"),"OK") -> OK
A34: Produtividade | B34: =03_Dashboard!$W$25 -> 3.3011364 | C34: 3.3011 | D34: Só se aplica com filtros em Todos e período completo | E34: =IF(AND(03_Dashboard!$G$6="Todos",03_Dashboard!$K$6="Todos",03_Dashboard!$O$6="Todos",03_Dashboard!$B$6=02_Parâmetros!$B$46,03_Dashboard!$D$6=02_Parâmetros!$B$47),IF(ROUND(B34,4)=C34,"OK","Divergente"),"OK") -> OK
A35: CSAT | B35: =03_Dashboard!$W$22 -> 0.80930233 | C35: 0.8093 | D35: Só se aplica com filtros em Todos e período completo | E35: =IF(AND(03_Dashboard!$G$6="Todos",03_Dashboard!$K$6="Todos",03_Dashboard!$O$6="Todos",03_Dashboard!$B$6=02_Parâmetros!$B$46,03_Dashboard!$D$6=02_Parâmetros!$B$47),IF(ROUND(B35,4)=C35,"OK","Divergente"),"OK") -> OK
A36: FCR | B36: =03_Dashboard!$W$24 -> 0.75731497 | C36: 0.7573 | D36: Só se aplica com filtros em Todos e período completo | E36: =IF(AND(03_Dashboard!$G$6="Todos",03_Dashboard!$K$6="Todos",03_Dashboard!$O$6="Todos",03_Dashboard!$B$6=02_Parâmetros!$B$46,03_Dashboard!$D$6=02_Parâmetros!$B$47),IF(ROUND(B36,4)=C36,"OK","Divergente"),"OK") -> OK
A38: Os valores esperados da última tabela são fixos (calculados fora do Excel). Se a base mudar, recalcule-os.
